<sdf version='1.7'>
  <model name='swimming_robot_assembly_new'>
    <link name='base_link_robot'>
      <inertial>
        <pose>1.4e-05 -8.1e-05 -0.042502 0 -0 0</pose>
        <mass>0.230252</mass>
        <inertia>
          <ixx>0.000125567</ixx>
          <ixy>-1.5295e-07</ixy>
          <ixz>4.49488e-09</ixz>
          <iyy>0.000161361</iyy>
          <iyz>-3.72274e-10</iyz>
          <izz>0.00013433</izz>
        </inertia>
      </inertial>
      <collision name='base_link_robot_collision'>
        <pose>0 0 0 0 -0 0</pose>
        <geometry>
          <mesh>
            <scale>1 1 1</scale>
            <uri>file://swimming_robot/world/meshes//base_link_robot.STL</uri>
          </mesh>
        </geometry>
      </collision>
      <collision name='base_link_robot_fixed_joint_lump__link_propstat1_collision_1'>
        <pose>-0.023 0 -0.0365 0 -0 0</pose>
        <geometry>
          <mesh>
            <scale>1 1 1</scale>
            <uri>file://swimming_robot/world/meshes//link_propstat1.STL</uri>
          </mesh>
        </geometry>
      </collision>
      <collision name='base_link_robot_fixed_joint_lump__link_propstat2_collision_2'>
        <pose>0.023 0 -0.0365 0 -0 0</pose>
        <geometry>
          <mesh>
            <scale>1 1 1</scale>
            <uri>file://swimming_robot/world/meshes//link_propstat2.STL</uri>
          </mesh>
        </geometry>
      </collision>
      <visual name='base_link_robot_visual'>
        <pose>0 0 0 0 -0 0</pose>
        <geometry>
          <mesh>
            <scale>1 1 1</scale>
            <uri>file://swimming_robot/world/meshes//base_link_robot.STL</uri>
          </mesh>
        </geometry>
      </visual>
      <visual name='base_link_robot_fixed_joint_lump__link_propstat1_visual_1'>
        <pose>-0.023 0 -0.0365 0 -0 0</pose>
        <geometry>
          <mesh>
            <scale>1 1 1</scale>
            <uri>file://swimming_robot/world/meshes//link_propstat1.STL</uri>
          </mesh>
        </geometry>
      </visual>
      <visual name='base_link_robot_fixed_joint_lump__link_propstat2_visual_2'>
        <pose>0.023 0 -0.0365 0 -0 0</pose>
        <geometry>
          <mesh>
            <scale>1 1 1</scale>
            <uri>file://swimming_robot/world/meshes//link_propstat2.STL</uri>
          </mesh>
        </geometry>
      </visual>
      <sensor type = "lidar" name = "sensor_fwd">
        <pose>0 0 0 0 0 0</pose>
        <visualize>true</visualize>
        <update_rate>40</update_rate>
        <always_on>1</always_on>
        <lidar>          
          <scan>
            <horizontal>
              <samples>320</samples>
              <resolution>0.9</resolution>
              <min_angle>1.75</min_angle>
              <max_angle>2.94</max_angle>
            </horizontal>

            <vertical>
              <samples>240</samples>
              <resolution>0.8</resolution>
              <min_angle>2.75</min_angle>
              <max_angle>3.94</max_angle>
            </vertical>
          </scan>

          <range>
            <min>1.23</min>
            <max>4.56</max>
            <resolution>7.89</resolution>
          </range>
          <noise type="gaussian">
            <mean>0.98</mean>
            <stddev>0.76</stddev>
          </noise>
        </lidar>
      </sensor>
      
      <sensor type = "lidar" name = "sensor_bwd">
        <pose>0 0 0.085 0 0 0</pose>
        <visualize>true</visualize>
        <update_rate>40</update_rate>
        <always_on>1</always_on>
        <lidar>          
          <scan>
            <horizontal>
              <samples>320</samples>
              <resolution>0.9</resolution>
              <min_angle>1.75</min_angle>
              <max_angle>2.94</max_angle>
            </horizontal>

            <vertical>
              <samples>240</samples>
              <resolution>0.8</resolution>
              <min_angle>2.75</min_angle>
              <max_angle>3.94</max_angle>
            </vertical>
          </scan>

          <range>
            <min>1.23</min>
            <max>4.56</max>
            <resolution>7.89</resolution>
          </range>
          <noise type="gaussian">
            <mean>0.98</mean>
            <stddev>0.76</stddev>
          </noise>
        </lidar>
      </sensor>
    </link>

    <joint name='act_proprotor1' type='revolute'>
      <pose relative_to='base_link_robot'>-0.023 0 -0.0365 0 -0 0</pose>
      <parent>base_link_robot</parent>
      <child>link_proprotor1</child>
      <axis>
        <xyz>0 0 -1</xyz>
        <limit>
          <effort>0.00068</effort>
          <velocity>0.1441</velocity>
          <lower>-3.14</lower>
          <upper>3.14</upper>
        </limit>
        <dynamics>
          <damping>0 0 4.21</damping>
          <friction>0 0 13</friction>
          <spring_reference>0</spring_reference>
          <spring_stiffness>0 9.8 0</spring_stiffness>
        </dynamics>
      <physics>
        <ode>
          <bounce>0.25 0.25 0.25</bounce>
          <max_force>0 9.8 0.36</max_force>
          <velocity>0 0 3</velocity>
        </ode>
      </physics>
      </axis>
    </joint>
    <link name='link_proprotor1'>
      <pose relative_to='act_proprotor1'>0 0 0 0 -0 0</pose>
      <inertial>
        <pose>-3e-06 -3e-06 -0.00606 0 -0 0</pose>
        <mass>0.0069922</mass>
        <inertia>
          <ixx>2.9861e-07</ixx>
          <ixy>-1.599e-13</ixy>
          <ixz>8.2506e-13</ixz>
          <iyy>2.9861e-07</iyy>
          <iyz>6.7843e-13</iyz>
          <izz>4.2964e-07</izz>
        </inertia>
      </inertial>
      <collision name='link_proprotor1_collision'>
        <pose>0 0 0 0 -0 0</pose>
        <geometry>
          <mesh>
            <scale>1 1 1</scale>
            <uri>file://swimming_robot/world/meshes//link_proprotor1.STL</uri>
          </mesh>
        </geometry>
      </collision>
      <visual name='link_proprotor1_visual'>
        <pose>0 0 0 0 -0 0</pose>
        <geometry>
          <mesh>
            <scale>1 1 1</scale>
            <uri>file://swimming_robot/world/meshes//link_proprotor1.STL</uri>
          </mesh>
        </geometry>
      </visual>
    </link>
    <joint name='act_proprotor2' type='revolute'>
      <pose relative_to='base_link_robot'>0.023 0 -0.0365 0 -0 0</pose>
      <parent>base_link_robot</parent>
      <child>link_proprotor2</child>
      <axis>
        <xyz>0 0 -1</xyz>
        <limit>
          <effort>0.00068</effort>
          <velocity>0.1441</velocity>
          <lower>-3.14</lower>
          <upper>3.14</upper>
        </limit>
        <dynamics>
          <damping>0 0 4.2</damping>
          <friction>0 0 13</friction>
          <spring_reference>0</spring_reference>
          <spring_stiffness>0 0 9.8</spring_stiffness>
        </dynamics>
        <physics>
        <ode>
          <bounce>0.25 0.25 0.25</bounce>
          <max_force>0 9.8 0.36</max_force>
          <velocity>0 0 3</velocity>
        </ode>
      </physics>
      </axis>
    </joint>
    <link name='link_proprotor2'>
      <pose relative_to='act_proprotor2'>0 0 0 0 -0 0</pose>
      <inertial>
        <pose>-3e-06 4e-06 -0.00606 0 -0 0</pose>
        <mass>0.0069922</mass>
        <inertia>
          <ixx>2.9861e-07</ixx>
          <ixy>1.5874e-13</ixy>
          <ixz>6.6396e-13</ixz>
          <iyy>2.9861e-07</iyy>
          <iyz>-8.3675e-13</iyz>
          <izz>4.2964e-07</izz>
        </inertia>
      </inertial>
      <collision name='link_proprotor2_collision'>
        <pose>0 0 0 0 -0 0</pose>
        <geometry>
          <mesh>
            <scale>1 1 1</scale>
            <uri>file://swimming_robot/world/meshes//link_proprotor2.STL</uri>
          </mesh>
        </geometry>
      </collision>
      <visual name='link_proprotor2_visual'>
        <pose>0 0 0 0 -0 0</pose>
        <geometry>
          <mesh>
            <scale>1 1 1</scale>
            <uri>file://swimming_robot/world/meshes//link_proprotor2.STL</uri>
          </mesh>
        </geometry>
      </visual>
    </link>
  </model>
</sdf>
